<mujoco model="rb20_1900es">
  <asset>
    <mesh name="rb20_1900es_rt_link0_visual_0" file="assets/generated/rb20_1900es_rt_link0_visual_0.obj" />
    <mesh name="rb20_1900es_rt_link0_collision_0" file="assets/generated/rb20_1900es_rt_link0_collision_0.obj" />
    <mesh name="rb20_1900es_rt_link1_visual_0" file="assets/generated/rb20_1900es_rt_link1_visual_0.obj" />
    <mesh name="rb20_1900es_rt_link1_collision_0" file="assets/generated/rb20_1900es_rt_link1_collision_0.obj" />
    <mesh name="rb20_1900es_rt_link2_visual_0" file="assets/generated/rb20_1900es_rt_link2_visual_0.obj" />
    <mesh name="rb20_1900es_rt_link2_collision_0" file="assets/generated/rb20_1900es_rt_link2_collision_0.obj" />
    <mesh name="rb20_1900es_rt_link3_visual_0" file="assets/generated/rb20_1900es_rt_link3_visual_0.obj" />
    <mesh name="rb20_1900es_rt_link3_collision_0" file="assets/generated/rb20_1900es_rt_link3_collision_0.obj" />
    <mesh name="rb20_1900es_rt_link4_visual_0" file="assets/generated/rb20_1900es_rt_link4_visual_0.obj" />
    <mesh name="rb20_1900es_rt_link4_collision_0" file="assets/generated/rb20_1900es_rt_link4_collision_0.obj" />
    <mesh name="rb20_1900es_rt_link5_visual_0" file="assets/generated/rb20_1900es_rt_link5_visual_0.obj" />
    <mesh name="rb20_1900es_rt_link5_collision_0" file="assets/generated/rb20_1900es_rt_link5_collision_0.obj" />
    <mesh name="rb20_1900es_rt_link6_visual_0" file="assets/generated/rb20_1900es_rt_link6_visual_0.obj" />
    <mesh name="rb20_1900es_rt_link6_collision_0" file="assets/generated/rb20_1900es_rt_link6_collision_0.obj" />
    <mesh name="rb20_1900es_rt_link_end_visual_0" file="assets/generated/rb20_1900es_rt_link_end_visual_0.obj" scale="0.001 0.001 0.001" />
    <mesh name="rb20_1900es_rt_link_end_collision_0" file="assets/generated/rb20_1900es_rt_link_end_collision_0.obj" scale="0.001 0.001 0.001" />
  </asset>
  <worldbody>
    <body name="rb20_1900es_base" pos="0 0 0" euler="0 0 0">
      <body name="rt_link_linear_track">
        <inertial pos="4.15 0 0.1" mass="100.0" diaginertia="1.0 1.0 1.0" />
        <geom name="rb20_1900es_rt_link_linear_track_visual_0" pos="4.15 0 0.1" euler="0 0 0" rgba="0.1 0.1 0.1 1" contype="0" conaffinity="0" group="1" type="box" size="4.15 0.2 0.1" />
        <geom name="rb20_1900es_rt_link_linear_track_collision_0" pos="4.15 0 0.1" euler="0 0 0" rgba="1 0 0 0.18" contype="1" conaffinity="1" group="3" condim="3" friction="1 0.005 0.0001" solref="0.01 1" solimp="0.9 0.95 0.001" type="box" size="4.15 0.2 0.1" />
        <body name="rt_link_carriage" pos="0 0 0.2" euler="0 0 0">
          <inertial pos="0 0.25 0.05" mass="50.0" diaginertia="1.0 1.0 1.0" />
          <joint name="rt_joint_linear_track" type="slide" axis="1 0 0" range="0.0 7.9" actuatorfrcrange="-1000.0 1000.0" damping="80" armature="0.1" />
          <geom name="rb20_1900es_rt_link_carriage_visual_0" pos="0.2 0 0.1" euler="0 0 0" rgba="0.1 0.1 0.1 1" contype="0" conaffinity="0" group="1" type="box" size="0.2 0.35 0.1" />
          <geom name="rb20_1900es_rt_link_carriage_collision_0" pos="0 0.25 0.05" euler="0 0 0" rgba="1 0 0 0.18" contype="1" conaffinity="1" group="3" condim="3" friction="1 0.005 0.0001" solref="0.01 1" solimp="0.9 0.95 0.001" type="box" size="0.2 0.25 0.05" />
          <body name="rt_link0" pos="0.2 0 0.2" euler="0 0 0">
            <inertial pos="0 0 0" mass="1" diaginertia="0.01 0.01 0.01" />
            <joint name="rt_joint_carriage" type="slide" axis="0 1 0" range="0.0 0.5" actuatorfrcrange="-1000.0 1000.0" damping="80" armature="0.1" />
            <geom name="rb20_1900es_rt_link0_visual_0" pos="0 0 0" euler="0 0 1.570796327" rgba="0.25 0.45 0.6 0.9" contype="0" conaffinity="0" group="1" type="mesh" mesh="rb20_1900es_rt_link0_visual_0" />
            <geom name="rb20_1900es_rt_link0_collision_0" pos="0 0 0" euler="0 0 1.570796327" rgba="1 0 0 0.18" contype="1" conaffinity="1" group="3" condim="3" friction="1 0.005 0.0001" solref="0.01 1" solimp="0.9 0.95 0.001" type="mesh" mesh="rb20_1900es_rt_link0_collision_0" />
            <body name="rt_link1" pos="0 0 0.241" euler="0 0 1.570796327">
              <inertial pos="0 -0.008 -0.056" mass="15.48" diaginertia="0.084 0.084 0.067" />
              <joint name="rt_base" type="hinge" axis="0 0 1" range="-3.14 3.14" actuatorfrcrange="-10 10" damping="8" armature="0.05" />
              <geom name="rb20_1900es_rt_link1_visual_0" pos="0 0 0" euler="0 0 0" rgba="0.25 0.45 0.6 0.9" contype="0" conaffinity="0" group="1" type="mesh" mesh="rb20_1900es_rt_link1_visual_0" />
              <geom name="rb20_1900es_rt_link1_collision_0" pos="0 0 0" euler="0 0 0" rgba="1 0 0 0.18" contype="1" conaffinity="1" group="3" condim="3" friction="1 0.005 0.0001" solref="0.01 1" solimp="0.9 0.95 0.001" type="mesh" mesh="rb20_1900es_rt_link1_collision_0" />
              <body name="rt_link2" pos="0 -0.2545 0" euler="0 0 0">
                <inertial pos="-0 -0.217 0.341" mass="32.79" diaginertia="4.81 4.773 0.175" />
                <joint name="rt_shoulder" type="hinge" axis="0 1 0" range="-3.14 3.14" actuatorfrcrange="-10 10" damping="3" armature="0.1" />
                <geom name="rb20_1900es_rt_link2_visual_0" pos="0 0 0" euler="0 0 0" rgba="0.25 0.45 0.6 0.9" contype="0" conaffinity="0" group="1" type="mesh" mesh="rb20_1900es_rt_link2_visual_0" />
                <geom name="rb20_1900es_rt_link2_collision_0" pos="0 0 0" euler="0 0 0" rgba="1 0 0 0.18" contype="1" conaffinity="1" group="3" condim="3" friction="1 0.005 0.0001" solref="0.01 1" solimp="0.9 0.95 0.001" type="mesh" mesh="rb20_1900es_rt_link2_collision_0" />
                <body name="rt_link3" pos="0 0 0.885" euler="0 0 0">
                  <inertial pos="0 -0.008 0.042" mass="8.371" diaginertia="0.027 0.028 0.026" />
                  <joint name="rt_elbow" type="hinge" axis="0 1 0" range="-3.14 3.14" actuatorfrcrange="-10 10" damping="3" armature="0.1" />
                  <geom name="rb20_1900es_rt_link3_visual_0" pos="0 0 0" euler="0 0 0" rgba="0.25 0.45 0.6 0.9" contype="0" conaffinity="0" group="1" type="mesh" mesh="rb20_1900es_rt_link3_visual_0" />
                  <geom name="rb20_1900es_rt_link3_collision_0" pos="0 0 0" euler="0 0 0" rgba="1 0 0 0.18" contype="1" conaffinity="1" group="3" condim="3" friction="1 0.005 0.0001" solref="0.01 1" solimp="0.9 0.95 0.001" type="mesh" mesh="rb20_1900es_rt_link3_collision_0" />
                  <body name="rt_link4" pos="0 0.1875 0" euler="0 0 0">
                    <inertial pos="0 -0.068 0.505" mass="8.14" diaginertia="0.718 0.696 0.046" />
                    <joint name="rt_wrist1" type="hinge" axis="0 0 1" range="-3.14 3.14" actuatorfrcrange="-10 10" damping="8" armature="0.05" />
                    <geom name="rb20_1900es_rt_link4_visual_0" pos="0 0 0" euler="0 0 0" rgba="0.25 0.45 0.6 0.9" contype="0" conaffinity="0" group="1" type="mesh" mesh="rb20_1900es_rt_link4_visual_0" />
                    <geom name="rb20_1900es_rt_link4_collision_0" pos="0 0 0" euler="0 0 0" rgba="1 0 0 0.18" contype="1" conaffinity="1" group="3" condim="3" friction="1 0.005 0.0001" solref="0.01 1" solimp="0.9 0.95 0.001" type="mesh" mesh="rb20_1900es_rt_link4_collision_0" />
                    <body name="rt_link5" pos="0 -0.1292 0.885" euler="0 0 0">
                      <inertial pos="0 0 0.035" mass="1.924" diaginertia="0.002 0.002 0.002" />
                      <joint name="rt_wrist2" type="hinge" axis="0 1 0" range="-3.14 3.14" actuatorfrcrange="-10 10" damping="8" armature="0.05" />
                      <geom name="rb20_1900es_rt_link5_visual_0" pos="0 0 0" euler="0 0 0" rgba="0.25 0.45 0.6 0.9" contype="0" conaffinity="0" group="1" type="mesh" mesh="rb20_1900es_rt_link5_visual_0" />
                      <geom name="rb20_1900es_rt_link5_collision_0" pos="0 0 0" euler="0 0 0" rgba="1 0 0 0.18" contype="1" conaffinity="1" group="3" condim="3" friction="1 0.005 0.0001" solref="0.01 1" solimp="0.9 0.95 0.001" type="mesh" mesh="rb20_1900es_rt_link5_collision_0" />
                      <body name="rt_link6" pos="0 0.1292 0" euler="0 0 0">
                        <inertial pos="0 0 0.104" mass="0.588" diaginertia="0.001 0.001 0.001" />
                        <joint name="rt_wrist3" type="hinge" axis="0 0 1" range="-3.14 3.14" actuatorfrcrange="-10 10" damping="8" armature="0.05" />
                        <geom name="rb20_1900es_rt_link6_visual_0" pos="0 0 0" euler="0 0 0" rgba="0.25 0.45 0.6 0.9" contype="0" conaffinity="0" group="1" type="mesh" mesh="rb20_1900es_rt_link6_visual_0" />
                        <geom name="rb20_1900es_rt_link6_collision_0" pos="0 0 0" euler="0 0 0" rgba="1 0 0 0.18" contype="1" conaffinity="1" group="3" condim="3" friction="1 0.005 0.0001" solref="0.01 1" solimp="0.9 0.95 0.001" type="mesh" mesh="rb20_1900es_rt_link6_collision_0" />
                        <body name="rt_link_end" pos="0 0 0.13" euler="-1.570796327 0 0">
                          <inertial pos="4.071342608e-05 -0.143110803 2.607058117e-05" mass="33.803183177691814" diaginertia="0.150633 0.230106 0.339619" />
                          <geom name="rb20_1900es_rt_link_end_visual_0" pos="-0 0.1163 -0" euler="0 0 0" rgba="0.9 0.9 0.1 1" contype="0" conaffinity="0" group="1" type="mesh" mesh="rb20_1900es_rt_link_end_visual_0" />
                          <geom name="rb20_1900es_rt_link_end_collision_0" pos="-0 0.1163 -0" euler="0 0 0" rgba="1 0 0 0.18" contype="1" conaffinity="1" group="3" condim="3" friction="1 0.005 0.0001" solref="0.01 1" solimp="0.9 0.95 0.001" type="mesh" mesh="rb20_1900es_rt_link_end_collision_0" />
                        </body>
                        <body name="rt_tcp" pos="0 -0.1153 0" euler="0 0 0">
                          <inertial pos="0 0 0" mass="1" diaginertia="0.01 0.01 0.01" />
                        </body>
                      </body>
                    </body>
                  </body>
                </body>
              </body>
            </body>
          </body>
        </body>
      </body>
    </body>
  </worldbody>
  <actuator>
    <position name="rt_joint_linear_track_pos" joint="rt_joint_linear_track" kp="300" kv="80" ctrlrange="0.0 7.9" forcerange="-1000.0 1000.0" />
    <position name="rt_joint_carriage_pos" joint="rt_joint_carriage" kp="300" kv="80" ctrlrange="0.0 0.5" forcerange="-1000.0 1000.0" />
    <position name="rt_base_pos" joint="rt_base" kp="40" kv="12" ctrlrange="-3.14 3.14" forcerange="-10 10" />
    <position name="rt_shoulder_pos" joint="rt_shoulder" kp="100" kv="30" ctrlrange="-3.14 3.14" forcerange="-10 10" />
    <position name="rt_elbow_pos" joint="rt_elbow" kp="100" kv="30" ctrlrange="-3.14 3.14" forcerange="-10 10" />
    <position name="rt_wrist1_pos" joint="rt_wrist1" kp="40" kv="12" ctrlrange="-3.14 3.14" forcerange="-10 10" />
    <position name="rt_wrist2_pos" joint="rt_wrist2" kp="40" kv="12" ctrlrange="-3.14 3.14" forcerange="-10 10" />
    <position name="rt_wrist3_pos" joint="rt_wrist3" kp="40" kv="12" ctrlrange="-3.14 3.14" forcerange="-10 10" />
  </actuator>
</mujoco>