<?xml version="1.0" ?>
<!-- =================================================================================== -->
<!-- |    This document was autogenerated by xacro from rb20_1900es.urdf.xacro         | -->
<!-- |    EDITING THIS FILE BY HAND IS NOT RECOMMENDED                                 | -->
<!-- =================================================================================== -->
<robot name="rt_rb20_1900es">
  <link name="rt_link_linear_track">
    <visual>
      <origin xyz="4.15 0 0.1" rpy="0 0 0" />
      <geometry>
        <box size="8.3 0.4 0.2" />
      </geometry>
      <material name="color_darkgray">
        <color rgba="0.1 0.1 0.1 1"/>
      </material>
    </visual>
    <collision>
      <origin xyz="4.15 0 0.1" rpy="0 0 0" />
      <geometry>
        <box size="8.3 0.4 0.2" />
      </geometry>
    </collision>
    <inertial>
      <origin xyz="4.15 0 0.1" rpy="0 0 0" />
      <mass value="100.0" />
      <inertia ixx="1.0" ixy="0.0" ixz="0.0" iyy="1.0" iyz="0.0" izz="1.0" />
    </inertial>
  </link>

  <joint name="rt_joint_linear_track" type="prismatic">
    <parent link="rt_link_linear_track" />
    <child link="rt_link_carriage" />
    <origin xyz="0 0 0.2" rpy="0 0 0" />
    <axis xyz="1 0 0" />
    <limit lower="0.0" upper="7.9" effort="1000.0" velocity="1.0" />
  </joint>

  <link name="rt_link_carriage">
    <visual>
      <origin xyz="0.2 0 0.1" rpy="0 0 0" />
      <geometry>
        <box size="0.4 0.7 0.2" />
      </geometry>
      <material name="color_darkgray">
        <color rgba="0.1 0.1 0.1 1"/>
      </material>
    </visual>
    <collision>
      <origin xyz="0 0.25 0.05" rpy="0 0 0" />
      <geometry>
        <box size="0.4 0.5 0.1" />
      </geometry>
    </collision>
    <inertial>
      <origin xyz="0 0.25 0.05" rpy="0 0 0" />
      <mass value="50.0" />
      <inertia ixx="1.0" ixy="0.0" ixz="0.0" iyy="1.0" iyz="0.0" izz="1.0" />
    </inertial>
  </link>

  <joint name="rt_joint_carriage" type="prismatic">
    <parent link="rt_link_carriage" />
    <child link="rt_link0" />
    <origin xyz="0.2 0 0.2" rpy="0 0 0" />
    <axis xyz="0 1 0" />
    <limit lower="0.0" upper="0.5" effort="1000.0" velocity="1.0" />
  </joint>

  <link name="rt_link0">
    <visual>
      <origin xyz="0 0 0" rpy="0 0 1.57079632679" />
      <geometry>
        <mesh filename="meshes/rb20_1900es/visual/link0.dae"/>
      </geometry>
    </visual>
    <collision>
      <origin xyz="0 0 0" rpy="0 0 1.57079632679" />
      <geometry>
        <mesh filename="meshes/rb20_1900es/collision/link0.stl"/>
      </geometry>
    </collision>
  </link>
  <link name="rt_link1">
    <visual>
      <geometry>
        <mesh filename="meshes/rb20_1900es/visual/link1.dae"/>
      </geometry>
    </visual>
    <collision>
      <geometry>
        <mesh filename="meshes/rb20_1900es/collision/link1.stl"/>
      </geometry>
    </collision>
    <inertial>
      <origin rpy="0 0 0" xyz="0.000 -0.008 -0.056"/>
      <mass value="15.48"/>
      <inertia ixx="0.084" ixy="0.0" ixz="0.0" iyy="0.084" iyz="0.006" izz="0.067"/>
    </inertial>
  </link>
  <link name="rt_link2">
    <visual>
      <geometry>
        <mesh filename="meshes/rb20_1900es/visual/link2.dae"/>
      </geometry>
    </visual>
    <collision>
      <geometry>
        <mesh filename="meshes/rb20_1900es/collision/link2.stl"/>
      </geometry>
    </collision>
    <inertial>
      <origin rpy="0 0 0" xyz="-0.000 -0.217 0.341"/>
      <mass value="32.79"/>
      <inertia ixx="4.81" ixy="0.0" ixz="0.0" iyy="4.773" iyz="0.104" izz="0.175"/>
    </inertial>
  </link>
  <link name="rt_link3">
    <visual>
      <geometry>
        <mesh filename="meshes/rb20_1900es/visual/link3.dae"/>
      </geometry>
    </visual>
    <collision>
      <geometry>
        <mesh filename="meshes/rb20_1900es/collision/link3.stl"/>
      </geometry>
    </collision>
    <inertial>
      <origin rpy="0 0 0" xyz="0.0 -0.008 0.042"/>
      <mass value="8.371"/>
      <inertia ixx="0.027" ixy="0.0" ixz="0.0" iyy="0.028" iyz="-0.003" izz="0.026"/>
    </inertial>
  </link>
  <link name="rt_link4">
    <visual>
      <geometry>
        <mesh filename="meshes/rb20_1900es/visual/link4.dae"/>
      </geometry>
    </visual>
    <collision>
      <geometry>
        <mesh filename="meshes/rb20_1900es/collision/link4.stl"/>
      </geometry>
    </collision>
    <inertial>
      <origin rpy="0 0 0" xyz="0.0 -0.068 0.505"/>
      <mass value="8.14"/>
      <inertia ixx="0.718" ixy="0.0" ixz="0.0" iyy="0.696" iyz="0.099" izz="0.046"/>
    </inertial>
  </link>
  <link name="rt_link5">
    <visual>
      <geometry>
        <mesh filename="meshes/rb20_1900es/visual/link5.dae"/>
      </geometry>
    </visual>
    <collision>
      <geometry>
        <mesh filename="meshes/rb20_1900es/collision/link5.stl"/>
      </geometry>
    </collision>
    <inertial>
      <origin rpy="0 0 0" xyz="0.0 0.0 0.035"/>
      <mass value="1.924"/>
      <inertia ixx="0.002" ixy="0.0" ixz="0.0" iyy="0.002" iyz="0.0" izz="0.002"/>
    </inertial>
  </link>
  <link name="rt_link6">
    <visual>
      <geometry>
        <mesh filename="meshes/rb20_1900es/visual/link6.dae"/>
      </geometry>
    </visual>
    <collision>
      <geometry>
        <mesh filename="meshes/rb20_1900es/collision/link6.stl"/>
      </geometry>
    </collision>
    <inertial>
      <origin rpy="0 0 0" xyz="0.000 0.000 0.104"/>
      <mass value="0.588"/>
      <inertia ixx="0.001" ixy="0.0" ixz="0.0" iyy="0.001" iyz="0.0" izz="0.001"/>
    </inertial>
  </link>
  <link name="rt_link_end">
    <inertial>
      <origin xyz="4.07134260806985e-05 -0.14311080297190015 2.6070581174467356e-05" rpy="0 0 0" />
      <mass value="33.803183177691814" />
      <inertia ixx="0.150633" iyy="0.230106" izz="0.339619" ixy="0.000105" iyz="-2.9e-05" ixz="-1.1e-05" />
    </inertial>
    <visual>
      <origin xyz="-0.0 0.1163 -0.0" rpy="0 0 0" />
      <geometry>
        <mesh filename="meshes/link_rt.stl" scale="0.001 0.001 0.001" />
      </geometry>
      <material name="yellow">
        <color rgba="0.9 0.9 0.1 1"/>
      </material>
    </visual>
    <collision>
      <origin xyz="-0.0 0.1163 -0.0" rpy="0 0 0" />
      <geometry>
        <mesh filename="meshes/link_rt.stl" scale="0.001 0.001 0.001" />
      </geometry>
    </collision>
  </link>
  <link name="rt_tcp"/>
  <joint name="rt_base" type="revolute">
    <origin rpy="0 0 1.57079632679" xyz="0 0 0.241"/>
    <parent link="rt_link0"/>
    <child link="rt_link1"/>
    <axis xyz="0 0 1"/>
    <limit effort="10" lower="-3.14" upper="3.14" velocity="3.14"/>
  </joint>
  <joint name="rt_shoulder" type="revolute">
    <origin rpy="0 0 0" xyz="0 -0.2545 0"/>
    <parent link="rt_link1"/>
    <child link="rt_link2"/>
    <axis xyz="0 1 0"/>
    <limit effort="10" lower="-3.14" upper="3.14" velocity="3.14"/>
  </joint>
  <joint name="rt_elbow" type="revolute">
    <origin rpy="0 0 0" xyz="0 0 0.885"/>
    <parent link="rt_link2"/>
    <child link="rt_link3"/>
    <axis xyz="0 1 0"/>
    <limit effort="10" lower="-3.14" upper="3.14" velocity="3.14"/>
  </joint>
  <joint name="rt_wrist1" type="revolute">
    <origin rpy="0 0 0" xyz="0 0.1875 0"/>
    <parent link="rt_link3"/>
    <child link="rt_link4"/>
    <axis xyz="0 0 1"/>
    <limit effort="10" lower="-3.14" upper="3.14" velocity="3.14"/>
  </joint>
  <joint name="rt_wrist2" type="revolute">
    <origin rpy="0 0 0" xyz="0 -0.1292 0.885"/>
    <parent link="rt_link4"/>
    <child link="rt_link5"/>
    <axis xyz="0 1 0"/>
    <limit effort="10" lower="-3.14" upper="3.14" velocity="3.14"/>
  </joint>
  <joint name="rt_wrist3" type="revolute">
    <origin rpy="0 0 0" xyz="0 0.1292 0"/>
    <parent link="rt_link5"/>
    <child link="rt_link6"/>
    <axis xyz="0 0 1"/>
    <limit effort="10" lower="-3.14" upper="3.14" velocity="3.14"/>
  </joint>
  <joint name="rt_joint_end" type="fixed">
    <origin xyz="0.0 0.0 0.13" rpy="-1.57079632679 0 0" />
    <parent link="rt_link6" />
    <child link="rt_link_end" />
  </joint>
  <joint name="rt_tcp_joint" type="fixed">
    <origin rpy="0 0 0" xyz="0 -0.1153 0"/>
    <parent link="rt_link6"/>
    <child link="rt_tcp"/>
  </joint>
  <ros2_control name="RBPodoHardwareInterface" type="system">
    <hardware>
      <plugin>mock_components/GenericSystem</plugin>
      <param name="mock_sensor_commands">False</param>
      <param name="state_following_offset">0.0</param>
    </hardware>
    <joint name="rt_joint_linear_track">
      <param name="initial_position">0.0</param>
      <param name="torque_constant">1</param>
      <command_interface name="effort"/>
      <command_interface name="velocity"/>
      <command_interface name="position"/>
      <state_interface name="position"/>
      <state_interface name="effort"/>
    </joint>
    <joint name="rt_joint_carriage">
      <param name="initial_position">0.0</param>
      <param name="torque_constant">1</param>
      <command_interface name="effort"/>
      <command_interface name="velocity"/>
      <command_interface name="position"/>
      <state_interface name="position"/>
      <state_interface name="effort"/>
    </joint>
    <joint name="rt_base">
      <param name="initial_position">0.0</param>
      <param name="torque_constant">1</param>
      <command_interface name="effort"/>
      <command_interface name="velocity"/>
      <command_interface name="position"/>
      <state_interface name="position"/>
      <state_interface name="effort"/>
    </joint>
    <joint name="rt_shoulder">
      <param name="initial_position">0.0</param>
      <param name="torque_constant">1</param>
      <command_interface name="effort"/>
      <command_interface name="velocity"/>
      <command_interface name="position"/>
      <state_interface name="position"/>
      <state_interface name="effort"/>
    </joint>
    <joint name="rt_elbow">
      <param name="initial_position">0.0</param>
      <param name="torque_constant">1</param>
      <command_interface name="effort"/>
      <command_interface name="velocity"/>
      <command_interface name="position"/>
      <state_interface name="position"/>
      <state_interface name="effort"/>
    </joint>
    <joint name="rt_wrist1">
      <param name="initial_position">0.0</param>
      <param name="torque_constant">1</param>
      <command_interface name="effort"/>
      <command_interface name="velocity"/>
      <command_interface name="position"/>
      <state_interface name="position"/>
      <state_interface name="effort"/>
    </joint>
    <joint name="rt_wrist2">
      <param name="initial_position">0.0</param>
      <param name="torque_constant">1</param>
      <command_interface name="effort"/>
      <command_interface name="velocity"/>
      <command_interface name="position"/>
      <state_interface name="position"/>
      <state_interface name="effort"/>
    </joint>
    <joint name="rt_wrist3">
      <param name="initial_position">0.0</param>
      <param name="torque_constant">1</param>
      <command_interface name="effort"/>
      <command_interface name="velocity"/>
      <command_interface name="position"/>
      <state_interface name="position"/>
      <state_interface name="effort"/>
    </joint>
    
  </ros2_control>
</robot>
